{
 "cells": [
  {
   "cell_type": "code",
   "execution_count": 7,
   "id": "f3aa67ba",
   "metadata": {},
   "outputs": [
    {
     "name": "stdout",
     "output_type": "stream",
     "text": [
      "Collecting keras_vggface\n",
      "  Downloading keras_vggface-0.6-py3-none-any.whl (8.3 kB)\n",
      "Requirement already satisfied: scipy>=0.14 in /home/administrator/anaconda3/envs/facerecognition/lib/python3.9/site-packages (from keras_vggface) (1.7.3)\n",
      "Requirement already satisfied: six>=1.9.0 in /home/administrator/anaconda3/envs/facerecognition/lib/python3.9/site-packages (from keras_vggface) (1.16.0)\n",
      "Requirement already satisfied: pillow in /home/administrator/anaconda3/envs/facerecognition/lib/python3.9/site-packages (from keras_vggface) (9.2.0)\n",
      "Requirement already satisfied: h5py in /home/administrator/anaconda3/envs/facerecognition/lib/python3.9/site-packages (from keras_vggface) (3.7.0)\n",
      "Requirement already satisfied: keras in /home/administrator/anaconda3/envs/facerecognition/lib/python3.9/site-packages (from keras_vggface) (2.11.0)\n",
      "Requirement already satisfied: numpy>=1.9.1 in /home/administrator/anaconda3/envs/facerecognition/lib/python3.9/site-packages (from keras_vggface) (1.21.5)\n",
      "Requirement already satisfied: pyyaml in /home/administrator/anaconda3/envs/facerecognition/lib/python3.9/site-packages (from keras_vggface) (6.0)\n",
      "Installing collected packages: keras_vggface\n",
      "Successfully installed keras_vggface-0.6\n"
     ]
    }
   ],
   "source": [
    "!pip install keras_vggface"
   ]
  },
  {
   "cell_type": "code",
   "execution_count": 9,
   "id": "52b7b9d6",
   "metadata": {},
   "outputs": [
    {
     "name": "stdout",
     "output_type": "stream",
     "text": [
      "Collecting keras_applications\n",
      "  Using cached Keras_Applications-1.0.8-py3-none-any.whl (50 kB)\n",
      "Requirement already satisfied: h5py in /home/administrator/anaconda3/envs/facerecognition/lib/python3.9/site-packages (from keras_applications) (3.7.0)\n",
      "Requirement already satisfied: numpy>=1.9.1 in /home/administrator/anaconda3/envs/facerecognition/lib/python3.9/site-packages (from keras_applications) (1.21.5)\n",
      "Installing collected packages: keras_applications\n",
      "Successfully installed keras_applications-1.0.8\n"
     ]
    }
   ],
   "source": [
    "!pip install keras_applications"
   ]
  },
  {
   "cell_type": "code",
   "execution_count": 10,
   "id": "90aaf509",
   "metadata": {},
   "outputs": [
    {
     "ename": "ModuleNotFoundError",
     "evalue": "No module named 'keras.engine.topology'",
     "output_type": "error",
     "traceback": [
      "\u001b[0;31m---------------------------------------------------------------------------\u001b[0m",
      "\u001b[0;31mModuleNotFoundError\u001b[0m                       Traceback (most recent call last)",
      "\u001b[0;32m/tmp/ipykernel_8876/3345631300.py\u001b[0m in \u001b[0;36m<module>\u001b[0;34m\u001b[0m\n\u001b[0;32m----> 1\u001b[0;31m \u001b[0;32mfrom\u001b[0m \u001b[0mkeras_vggface\u001b[0m\u001b[0;34m.\u001b[0m\u001b[0mvggface\u001b[0m \u001b[0;32mimport\u001b[0m \u001b[0mVGGFace\u001b[0m\u001b[0;34m\u001b[0m\u001b[0;34m\u001b[0m\u001b[0m\n\u001b[0m",
      "\u001b[0;32m/home/administrator/anaconda3/envs/facerecognition/lib/python3.9/site-packages/keras_vggface/__init__.py\u001b[0m in \u001b[0;36m<module>\u001b[0;34m\u001b[0m\n\u001b[0;32m----> 1\u001b[0;31m \u001b[0;32mfrom\u001b[0m \u001b[0mkeras_vggface\u001b[0m\u001b[0;34m.\u001b[0m\u001b[0mvggface\u001b[0m \u001b[0;32mimport\u001b[0m \u001b[0mVGGFace\u001b[0m\u001b[0;34m\u001b[0m\u001b[0;34m\u001b[0m\u001b[0m\n\u001b[0m\u001b[1;32m      2\u001b[0m \u001b[0;32mfrom\u001b[0m \u001b[0mkeras_vggface\u001b[0m\u001b[0;34m.\u001b[0m\u001b[0mversion\u001b[0m \u001b[0;32mimport\u001b[0m \u001b[0m__version__\u001b[0m\u001b[0;34m\u001b[0m\u001b[0;34m\u001b[0m\u001b[0m\n",
      "\u001b[0;32m/home/administrator/anaconda3/envs/facerecognition/lib/python3.9/site-packages/keras_vggface/vggface.py\u001b[0m in \u001b[0;36m<module>\u001b[0;34m\u001b[0m\n\u001b[1;32m      7\u001b[0m '''\n\u001b[1;32m      8\u001b[0m \u001b[0;32mfrom\u001b[0m \u001b[0m__future__\u001b[0m \u001b[0;32mimport\u001b[0m \u001b[0mprint_function\u001b[0m\u001b[0;34m\u001b[0m\u001b[0;34m\u001b[0m\u001b[0m\n\u001b[0;32m----> 9\u001b[0;31m \u001b[0;32mfrom\u001b[0m \u001b[0mkeras_vggface\u001b[0m\u001b[0;34m.\u001b[0m\u001b[0mmodels\u001b[0m \u001b[0;32mimport\u001b[0m \u001b[0mRESNET50\u001b[0m\u001b[0;34m,\u001b[0m \u001b[0mVGG16\u001b[0m\u001b[0;34m,\u001b[0m \u001b[0mSENET50\u001b[0m\u001b[0;34m\u001b[0m\u001b[0;34m\u001b[0m\u001b[0m\n\u001b[0m\u001b[1;32m     10\u001b[0m \u001b[0;34m\u001b[0m\u001b[0m\n\u001b[1;32m     11\u001b[0m \u001b[0;34m\u001b[0m\u001b[0m\n",
      "\u001b[0;32m/home/administrator/anaconda3/envs/facerecognition/lib/python3.9/site-packages/keras_vggface/models.py\u001b[0m in \u001b[0;36m<module>\u001b[0;34m\u001b[0m\n\u001b[1;32m     18\u001b[0m \u001b[0;32mfrom\u001b[0m \u001b[0mkeras\u001b[0m \u001b[0;32mimport\u001b[0m \u001b[0mbackend\u001b[0m \u001b[0;32mas\u001b[0m \u001b[0mK\u001b[0m\u001b[0;34m\u001b[0m\u001b[0;34m\u001b[0m\u001b[0m\n\u001b[1;32m     19\u001b[0m \u001b[0;32mfrom\u001b[0m \u001b[0mkeras_vggface\u001b[0m \u001b[0;32mimport\u001b[0m \u001b[0mutils\u001b[0m\u001b[0;34m\u001b[0m\u001b[0;34m\u001b[0m\u001b[0m\n\u001b[0;32m---> 20\u001b[0;31m \u001b[0;32mfrom\u001b[0m \u001b[0mkeras\u001b[0m\u001b[0;34m.\u001b[0m\u001b[0mengine\u001b[0m\u001b[0;34m.\u001b[0m\u001b[0mtopology\u001b[0m \u001b[0;32mimport\u001b[0m \u001b[0mget_source_inputs\u001b[0m\u001b[0;34m\u001b[0m\u001b[0;34m\u001b[0m\u001b[0m\n\u001b[0m\u001b[1;32m     21\u001b[0m \u001b[0;32mimport\u001b[0m \u001b[0mwarnings\u001b[0m\u001b[0;34m\u001b[0m\u001b[0;34m\u001b[0m\u001b[0m\n\u001b[1;32m     22\u001b[0m \u001b[0;32mfrom\u001b[0m \u001b[0mkeras\u001b[0m\u001b[0;34m.\u001b[0m\u001b[0mmodels\u001b[0m \u001b[0;32mimport\u001b[0m \u001b[0mModel\u001b[0m\u001b[0;34m\u001b[0m\u001b[0;34m\u001b[0m\u001b[0m\n",
      "\u001b[0;31mModuleNotFoundError\u001b[0m: No module named 'keras.engine.topology'"
     ]
    }
   ],
   "source": [
    "from keras_vggface.vggface import VGGFace"
   ]
  },
  {
   "cell_type": "code",
   "execution_count": 3,
   "id": "0b73d02c",
   "metadata": {},
   "outputs": [],
   "source": [
    "img1_path = 'deepface/tests/dataset/img1.jpg'\n",
    "img2_path = 'deepface/tests/dataset/img2.jpg'"
   ]
  },
  {
   "cell_type": "code",
   "execution_count": 4,
   "id": "7841d772",
   "metadata": {},
   "outputs": [],
   "source": [
    "model_name = 'Facenet'"
   ]
  },
  {
   "cell_type": "code",
   "execution_count": 6,
   "id": "be2ac6f9",
   "metadata": {},
   "outputs": [
    {
     "ename": "ValueError",
     "evalue": "Passed db_path does not exist!",
     "output_type": "error",
     "traceback": [
      "\u001b[0;31m---------------------------------------------------------------------------\u001b[0m",
      "\u001b[0;31mValueError\u001b[0m                                Traceback (most recent call last)",
      "\u001b[0;32m/tmp/ipykernel_8876/505594852.py\u001b[0m in \u001b[0;36m<module>\u001b[0;34m\u001b[0m\n\u001b[0;32m----> 1\u001b[0;31m \u001b[0mresp\u001b[0m \u001b[0;34m=\u001b[0m \u001b[0mDeepFace\u001b[0m\u001b[0;34m.\u001b[0m\u001b[0mfind\u001b[0m\u001b[0;34m(\u001b[0m\u001b[0mimg_path\u001b[0m \u001b[0;34m=\u001b[0m \u001b[0mimg1_path\u001b[0m\u001b[0;34m,\u001b[0m \u001b[0mdb_path\u001b[0m \u001b[0;34m=\u001b[0m \u001b[0;34m\"C:/facial_db\"\u001b[0m\u001b[0;34m)\u001b[0m\u001b[0;34m\u001b[0m\u001b[0;34m\u001b[0m\u001b[0m\n\u001b[0m",
      "\u001b[0;32m/home/administrator/anaconda3/envs/facerecognition/lib/python3.9/site-packages/deepface/DeepFace.py\u001b[0m in \u001b[0;36mfind\u001b[0;34m(img_path, db_path, model_name, distance_metric, model, enforce_detection, detector_backend, align, prog_bar, normalization, silent)\u001b[0m\n\u001b[1;32m    715\u001b[0m \u001b[0;34m\u001b[0m\u001b[0m\n\u001b[1;32m    716\u001b[0m         \u001b[0;32melse\u001b[0m\u001b[0;34m:\u001b[0m\u001b[0;34m\u001b[0m\u001b[0;34m\u001b[0m\u001b[0m\n\u001b[0;32m--> 717\u001b[0;31m                 \u001b[0;32mraise\u001b[0m \u001b[0mValueError\u001b[0m\u001b[0;34m(\u001b[0m\u001b[0;34m\"Passed db_path does not exist!\"\u001b[0m\u001b[0;34m)\u001b[0m\u001b[0;34m\u001b[0m\u001b[0;34m\u001b[0m\u001b[0m\n\u001b[0m\u001b[1;32m    718\u001b[0m \u001b[0;34m\u001b[0m\u001b[0m\n\u001b[1;32m    719\u001b[0m         \u001b[0;32mreturn\u001b[0m \u001b[0;32mNone\u001b[0m\u001b[0;34m\u001b[0m\u001b[0;34m\u001b[0m\u001b[0m\n",
      "\u001b[0;31mValueError\u001b[0m: Passed db_path does not exist!"
     ]
    }
   ],
   "source": [
    "resp = DeepFace.find(img_path = img1_path, db_path = \"C:/facial_db\")"
   ]
  },
  {
   "cell_type": "code",
   "execution_count": null,
   "id": "93badee7",
   "metadata": {},
   "outputs": [],
   "source": []
  }
 ],
 "metadata": {
  "kernelspec": {
   "display_name": "Python 3 (ipykernel)",
   "language": "python",
   "name": "python3"
  },
  "language_info": {
   "codemirror_mode": {
    "name": "ipython",
    "version": 3
   },
   "file_extension": ".py",
   "mimetype": "text/x-python",
   "name": "python",
   "nbconvert_exporter": "python",
   "pygments_lexer": "ipython3",
   "version": "3.9.15"
  }
 },
 "nbformat": 4,
 "nbformat_minor": 5
}
